[2023-01-08 11:07:10,724] {taskinstance.py:1179} INFO - Dependencies all met for <TaskInstance: Lead_Scoring_Data_Engineering_Pipeline_test.mapping_city_tier_test manual__2023-01-08T11:07:06.190968+00:00 [queued]>
[2023-01-08 11:07:10,729] {taskinstance.py:1179} INFO - Dependencies all met for <TaskInstance: Lead_Scoring_Data_Engineering_Pipeline_test.mapping_city_tier_test manual__2023-01-08T11:07:06.190968+00:00 [queued]>
[2023-01-08 11:07:10,729] {taskinstance.py:1376} INFO - 
--------------------------------------------------------------------------------
[2023-01-08 11:07:10,729] {taskinstance.py:1377} INFO - Starting attempt 1 of 2
[2023-01-08 11:07:10,729] {taskinstance.py:1378} INFO - 
--------------------------------------------------------------------------------
[2023-01-08 11:07:10,741] {taskinstance.py:1397} INFO - Executing <Task(PythonOperator): mapping_city_tier_test> on 2023-01-08 11:07:06.190968+00:00
[2023-01-08 11:07:10,744] {standard_task_runner.py:52} INFO - Started process 19612 to run task
[2023-01-08 11:07:10,749] {standard_task_runner.py:79} INFO - Running: ['airflow', 'tasks', 'run', 'Lead_Scoring_Data_Engineering_Pipeline_test', 'mapping_city_tier_test', 'manual__2023-01-08T11:07:06.190968+00:00', '--job-id', '98', '--raw', '--subdir', 'DAGS_FOLDER/Lead_scoring_data_pipeline/unit_test/.ipynb_checkpoints/lead_scoring_data_pipeline_test-checkpoint.py', '--cfg-path', '/tmp/tmpanog_8r2', '--error-file', '/tmp/tmpdphis6ac']
[2023-01-08 11:07:10,750] {standard_task_runner.py:80} INFO - Job 98: Subtask mapping_city_tier_test
[2023-01-08 11:07:10,787] {task_command.py:371} INFO - Running <TaskInstance: Lead_Scoring_Data_Engineering_Pipeline_test.mapping_city_tier_test manual__2023-01-08T11:07:06.190968+00:00 [running]> on host 1f037b111ba5
[2023-01-08 11:07:10,824] {taskinstance.py:1589} INFO - Exporting the following env vars:
AIRFLOW_CTX_DAG_OWNER=airflow
AIRFLOW_CTX_DAG_ID=Lead_Scoring_Data_Engineering_Pipeline_test
AIRFLOW_CTX_TASK_ID=mapping_city_tier_test
AIRFLOW_CTX_EXECUTION_DATE=2023-01-08T11:07:06.190968+00:00
AIRFLOW_CTX_TRY_NUMBER=1
AIRFLOW_CTX_DAG_RUN_ID=manual__2023-01-08T11:07:06.190968+00:00
[2023-01-08 11:07:10,863] {taskinstance.py:1909} ERROR - Task failed with exception
Traceback (most recent call last):
  File "/opt/conda/lib/python3.8/site-packages/airflow/operators/python.py", line 171, in execute
    return_value = self.execute_callable()
  File "/opt/conda/lib/python3.8/site-packages/airflow/operators/python.py", line 189, in execute_callable
    return self.python_callable(*self.op_args, **self.op_kwargs)
  File "/home/airflow/dags/Lead_scoring_data_pipeline/unit_test/test_with_pytest.py", line 58, in test_map_city_tier
    assert df.equals(df_test)
AssertionError
[2023-01-08 11:07:10,866] {taskinstance.py:1415} INFO - Marking task as UP_FOR_RETRY. dag_id=Lead_Scoring_Data_Engineering_Pipeline_test, task_id=mapping_city_tier_test, execution_date=20230108T110706, start_date=20230108T110710, end_date=20230108T110710
[2023-01-08 11:07:10,878] {standard_task_runner.py:92} ERROR - Failed to execute job 98 for task mapping_city_tier_test (; 19612)
[2023-01-08 11:07:10,918] {local_task_job.py:156} INFO - Task exited with return code 1
[2023-01-08 11:07:10,941] {local_task_job.py:273} INFO - 0 downstream tasks scheduled from follow-on schedule check
