[2023-01-08 09:00:57,124] {taskinstance.py:1179} INFO - Dependencies all met for <TaskInstance: Lead_Scoring_Data_Engineering_Pipeline_test.mapping_city_tier_test manual__2023-01-08T09:00:51.382116+00:00 [queued]>
[2023-01-08 09:00:57,129] {taskinstance.py:1179} INFO - Dependencies all met for <TaskInstance: Lead_Scoring_Data_Engineering_Pipeline_test.mapping_city_tier_test manual__2023-01-08T09:00:51.382116+00:00 [queued]>
[2023-01-08 09:00:57,129] {taskinstance.py:1376} INFO - 
--------------------------------------------------------------------------------
[2023-01-08 09:00:57,129] {taskinstance.py:1377} INFO - Starting attempt 1 of 2
[2023-01-08 09:00:57,129] {taskinstance.py:1378} INFO - 
--------------------------------------------------------------------------------
[2023-01-08 09:00:57,143] {taskinstance.py:1397} INFO - Executing <Task(PythonOperator): mapping_city_tier_test> on 2023-01-08 09:00:51.382116+00:00
[2023-01-08 09:00:57,147] {standard_task_runner.py:52} INFO - Started process 4767 to run task
[2023-01-08 09:00:57,153] {standard_task_runner.py:79} INFO - Running: ['airflow', 'tasks', 'run', 'Lead_Scoring_Data_Engineering_Pipeline_test', 'mapping_city_tier_test', 'manual__2023-01-08T09:00:51.382116+00:00', '--job-id', '50', '--raw', '--subdir', 'DAGS_FOLDER/Lead_scoring_data_pipeline/unit_test/.ipynb_checkpoints/lead_scoring_data_pipeline_test-checkpoint.py', '--cfg-path', '/tmp/tmp_tvea5ti', '--error-file', '/tmp/tmp4wkl48dw']
[2023-01-08 09:00:57,155] {standard_task_runner.py:80} INFO - Job 50: Subtask mapping_city_tier_test
[2023-01-08 09:00:57,203] {task_command.py:371} INFO - Running <TaskInstance: Lead_Scoring_Data_Engineering_Pipeline_test.mapping_city_tier_test manual__2023-01-08T09:00:51.382116+00:00 [running]> on host 1f037b111ba5
[2023-01-08 09:00:57,260] {taskinstance.py:1589} INFO - Exporting the following env vars:
AIRFLOW_CTX_DAG_OWNER=airflow
AIRFLOW_CTX_DAG_ID=Lead_Scoring_Data_Engineering_Pipeline_test
AIRFLOW_CTX_TASK_ID=mapping_city_tier_test
AIRFLOW_CTX_EXECUTION_DATE=2023-01-08T09:00:51.382116+00:00
AIRFLOW_CTX_TRY_NUMBER=1
AIRFLOW_CTX_DAG_RUN_ID=manual__2023-01-08T09:00:51.382116+00:00
[2023-01-08 09:00:57,262] {taskinstance.py:1909} ERROR - Task failed with exception
Traceback (most recent call last):
  File "/opt/conda/lib/python3.8/site-packages/pandas/io/sql.py", line 2020, in execute
    cur.execute(*args, **kwargs)
sqlite3.OperationalError: no such table: map_city_tier

The above exception was the direct cause of the following exception:

Traceback (most recent call last):
  File "/opt/conda/lib/python3.8/site-packages/airflow/operators/python.py", line 171, in execute
    return_value = self.execute_callable()
  File "/opt/conda/lib/python3.8/site-packages/airflow/operators/python.py", line 189, in execute_callable
    return self.python_callable(*self.op_args, **self.op_kwargs)
  File "/home/airflow/dags/Lead_scoring_data_pipeline/unit_test/test_with_pytest.py", line 54, in test_map_city_tier
    df = pd.read_sql('select * from map_city_tier', conn1)
  File "/opt/conda/lib/python3.8/site-packages/pandas/io/sql.py", line 566, in read_sql
    return pandas_sql.read_query(
  File "/opt/conda/lib/python3.8/site-packages/pandas/io/sql.py", line 2080, in read_query
    cursor = self.execute(*args)
  File "/opt/conda/lib/python3.8/site-packages/pandas/io/sql.py", line 2032, in execute
    raise ex from exc
pandas.io.sql.DatabaseError: Execution failed on sql 'select * from map_city_tier': no such table: map_city_tier
[2023-01-08 09:00:57,267] {taskinstance.py:1415} INFO - Marking task as UP_FOR_RETRY. dag_id=Lead_Scoring_Data_Engineering_Pipeline_test, task_id=mapping_city_tier_test, execution_date=20230108T090051, start_date=20230108T090057, end_date=20230108T090057
[2023-01-08 09:00:57,279] {standard_task_runner.py:92} ERROR - Failed to execute job 50 for task mapping_city_tier_test (Execution failed on sql 'select * from map_city_tier': no such table: map_city_tier; 4767)
[2023-01-08 09:00:57,321] {local_task_job.py:156} INFO - Task exited with return code 1
[2023-01-08 09:00:57,349] {local_task_job.py:273} INFO - 0 downstream tasks scheduled from follow-on schedule check
