[2023-01-08 09:13:14,703] {taskinstance.py:1179} INFO - Dependencies all met for <TaskInstance: Lead_Scoring_Data_Engineering_Pipeline_test.mapping_interactions_test manual__2023-01-08T09:13:05.218977+00:00 [queued]>
[2023-01-08 09:13:14,708] {taskinstance.py:1179} INFO - Dependencies all met for <TaskInstance: Lead_Scoring_Data_Engineering_Pipeline_test.mapping_interactions_test manual__2023-01-08T09:13:05.218977+00:00 [queued]>
[2023-01-08 09:13:14,708] {taskinstance.py:1376} INFO - 
--------------------------------------------------------------------------------
[2023-01-08 09:13:14,708] {taskinstance.py:1377} INFO - Starting attempt 1 of 2
[2023-01-08 09:13:14,708] {taskinstance.py:1378} INFO - 
--------------------------------------------------------------------------------
[2023-01-08 09:13:14,720] {taskinstance.py:1397} INFO - Executing <Task(PythonOperator): mapping_interactions_test> on 2023-01-08 09:13:05.218977+00:00
[2023-01-08 09:13:14,724] {standard_task_runner.py:52} INFO - Started process 6319 to run task
[2023-01-08 09:13:14,731] {standard_task_runner.py:79} INFO - Running: ['airflow', 'tasks', 'run', 'Lead_Scoring_Data_Engineering_Pipeline_test', 'mapping_interactions_test', 'manual__2023-01-08T09:13:05.218977+00:00', '--job-id', '63', '--raw', '--subdir', 'DAGS_FOLDER/Lead_scoring_data_pipeline/unit_test/.ipynb_checkpoints/lead_scoring_data_pipeline_test-checkpoint.py', '--cfg-path', '/tmp/tmpjmmnascc', '--error-file', '/tmp/tmp1hs6wlrc']
[2023-01-08 09:13:14,733] {standard_task_runner.py:80} INFO - Job 63: Subtask mapping_interactions_test
[2023-01-08 09:13:14,780] {task_command.py:371} INFO - Running <TaskInstance: Lead_Scoring_Data_Engineering_Pipeline_test.mapping_interactions_test manual__2023-01-08T09:13:05.218977+00:00 [running]> on host 1f037b111ba5
[2023-01-08 09:13:14,828] {taskinstance.py:1589} INFO - Exporting the following env vars:
AIRFLOW_CTX_DAG_OWNER=airflow
AIRFLOW_CTX_DAG_ID=Lead_Scoring_Data_Engineering_Pipeline_test
AIRFLOW_CTX_TASK_ID=mapping_interactions_test
AIRFLOW_CTX_EXECUTION_DATE=2023-01-08T09:13:05.218977+00:00
AIRFLOW_CTX_TRY_NUMBER=1
AIRFLOW_CTX_DAG_RUN_ID=manual__2023-01-08T09:13:05.218977+00:00
[2023-01-08 09:13:14,902] {taskinstance.py:1909} ERROR - Task failed with exception
Traceback (most recent call last):
  File "/opt/conda/lib/python3.8/site-packages/airflow/operators/python.py", line 171, in execute
    return_value = self.execute_callable()
  File "/opt/conda/lib/python3.8/site-packages/airflow/operators/python.py", line 189, in execute_callable
    return self.python_callable(*self.op_args, **self.op_kwargs)
  File "/home/airflow/dags/Lead_scoring_data_pipeline/unit_test/test_with_pytest.py", line 107, in test_interactions_mapping
    assert df.equals(df_test)
AssertionError
[2023-01-08 09:13:14,905] {taskinstance.py:1415} INFO - Marking task as UP_FOR_RETRY. dag_id=Lead_Scoring_Data_Engineering_Pipeline_test, task_id=mapping_interactions_test, execution_date=20230108T091305, start_date=20230108T091314, end_date=20230108T091314
[2023-01-08 09:13:14,919] {standard_task_runner.py:92} ERROR - Failed to execute job 63 for task mapping_interactions_test (; 6319)
[2023-01-08 09:13:14,939] {local_task_job.py:156} INFO - Task exited with return code 1
[2023-01-08 09:13:14,962] {local_task_job.py:273} INFO - 0 downstream tasks scheduled from follow-on schedule check
