[2023-01-08 11:12:15,958] {taskinstance.py:1179} INFO - Dependencies all met for <TaskInstance: Lead_scoring_inference_pipeline.generating_models_prediction manual__2023-01-08T11:12:06.154125+00:00 [queued]>
[2023-01-08 11:12:15,963] {taskinstance.py:1179} INFO - Dependencies all met for <TaskInstance: Lead_scoring_inference_pipeline.generating_models_prediction manual__2023-01-08T11:12:06.154125+00:00 [queued]>
[2023-01-08 11:12:15,963] {taskinstance.py:1376} INFO - 
--------------------------------------------------------------------------------
[2023-01-08 11:12:15,963] {taskinstance.py:1377} INFO - Starting attempt 1 of 2
[2023-01-08 11:12:15,963] {taskinstance.py:1378} INFO - 
--------------------------------------------------------------------------------
[2023-01-08 11:12:15,973] {taskinstance.py:1397} INFO - Executing <Task(PythonOperator): generating_models_prediction> on 2023-01-08 11:12:06.154125+00:00
[2023-01-08 11:12:15,977] {standard_task_runner.py:52} INFO - Started process 20489 to run task
[2023-01-08 11:12:15,983] {standard_task_runner.py:79} INFO - Running: ['airflow', 'tasks', 'run', 'Lead_scoring_inference_pipeline', 'generating_models_prediction', 'manual__2023-01-08T11:12:06.154125+00:00', '--job-id', '110', '--raw', '--subdir', 'DAGS_FOLDER/Lead_scoring_inference_pipeline/.ipynb_checkpoints/lead_scoring_inference_pipeline-checkpoint.py', '--cfg-path', '/tmp/tmpr491nczq', '--error-file', '/tmp/tmp8q9w47oy']
[2023-01-08 11:12:15,985] {standard_task_runner.py:80} INFO - Job 110: Subtask generating_models_prediction
[2023-01-08 11:12:16,027] {task_command.py:371} INFO - Running <TaskInstance: Lead_scoring_inference_pipeline.generating_models_prediction manual__2023-01-08T11:12:06.154125+00:00 [running]> on host 1f037b111ba5
[2023-01-08 11:12:16,165] {taskinstance.py:1589} INFO - Exporting the following env vars:
AIRFLOW_CTX_DAG_OWNER=airflow
AIRFLOW_CTX_DAG_ID=Lead_scoring_inference_pipeline
AIRFLOW_CTX_TASK_ID=generating_models_prediction
AIRFLOW_CTX_EXECUTION_DATE=2023-01-08T11:12:06.154125+00:00
AIRFLOW_CTX_TRY_NUMBER=1
AIRFLOW_CTX_DAG_RUN_ID=manual__2023-01-08T11:12:06.154125+00:00
[2023-01-08 11:12:16,239] {taskinstance.py:1909} ERROR - Task failed with exception
Traceback (most recent call last):
  File "/opt/conda/lib/python3.8/site-packages/airflow/operators/python.py", line 171, in execute
    return_value = self.execute_callable()
  File "/opt/conda/lib/python3.8/site-packages/airflow/operators/python.py", line 189, in execute_callable
    return self.python_callable(*self.op_args, **self.op_kwargs)
  File "/home/airflow/dags/Lead_scoring_inference_pipeline/utils.py", line 113, in get_models_prediction
    loaded_model = mlflow.pyfunc.load_model(
  File "/opt/conda/lib/python3.8/site-packages/mlflow/pyfunc/__init__.py", line 716, in load_model
    local_path = _download_artifact_from_uri(artifact_uri=model_uri, output_path=dst_path)
  File "/opt/conda/lib/python3.8/site-packages/mlflow/tracking/artifact_utils.py", line 94, in _download_artifact_from_uri
    return get_artifact_repository(artifact_uri=root_uri).download_artifacts(
  File "/opt/conda/lib/python3.8/site-packages/mlflow/store/artifact/artifact_repository_registry.py", line 107, in get_artifact_repository
    return _artifact_repository_registry.get_artifact_repository(artifact_uri)
  File "/opt/conda/lib/python3.8/site-packages/mlflow/store/artifact/artifact_repository_registry.py", line 73, in get_artifact_repository
    return repository(artifact_uri)
  File "/opt/conda/lib/python3.8/site-packages/mlflow/store/artifact/models_artifact_repo.py", line 35, in __init__
    uri = ModelsArtifactRepository.get_underlying_uri(artifact_uri)
  File "/opt/conda/lib/python3.8/site-packages/mlflow/store/artifact/models_artifact_repo.py", line 68, in get_underlying_uri
    (name, version) = get_model_name_and_version(client, uri)
  File "/opt/conda/lib/python3.8/site-packages/mlflow/store/artifact/utils/models.py", line 74, in get_model_name_and_version
    return model_name, str(_get_latest_model_version(client, model_name, model_stage))
  File "/opt/conda/lib/python3.8/site-packages/mlflow/store/artifact/utils/models.py", line 31, in _get_latest_model_version
    raise MlflowException(
mlflow.exceptions.MlflowException: No versions of model with name 'LightGBM' and stage 'Production' found
[2023-01-08 11:12:16,244] {taskinstance.py:1415} INFO - Marking task as UP_FOR_RETRY. dag_id=Lead_scoring_inference_pipeline, task_id=generating_models_prediction, execution_date=20230108T111206, start_date=20230108T111215, end_date=20230108T111216
[2023-01-08 11:12:16,255] {standard_task_runner.py:92} ERROR - Failed to execute job 110 for task generating_models_prediction (No versions of model with name 'LightGBM' and stage 'Production' found; 20489)
[2023-01-08 11:12:16,272] {local_task_job.py:156} INFO - Task exited with return code 1
[2023-01-08 11:12:16,298] {local_task_job.py:273} INFO - 0 downstream tasks scheduled from follow-on schedule check
