[2023-01-08 10:01:48,522] {taskinstance.py:1179} INFO - Dependencies all met for <TaskInstance: Lead_scoring_inference_pipeline.generating_models_prediction scheduled__2023-01-08T09:00:00+00:00 [queued]>
[2023-01-08 10:01:48,527] {taskinstance.py:1179} INFO - Dependencies all met for <TaskInstance: Lead_scoring_inference_pipeline.generating_models_prediction scheduled__2023-01-08T09:00:00+00:00 [queued]>
[2023-01-08 10:01:48,527] {taskinstance.py:1376} INFO - 
--------------------------------------------------------------------------------
[2023-01-08 10:01:48,527] {taskinstance.py:1377} INFO - Starting attempt 2 of 2
[2023-01-08 10:01:48,527] {taskinstance.py:1378} INFO - 
--------------------------------------------------------------------------------
[2023-01-08 10:01:48,537] {taskinstance.py:1397} INFO - Executing <Task(PythonOperator): generating_models_prediction> on 2023-01-08 09:00:00+00:00
[2023-01-08 10:01:48,543] {standard_task_runner.py:52} INFO - Started process 11184 to run task
[2023-01-08 10:01:48,549] {standard_task_runner.py:79} INFO - Running: ['airflow', 'tasks', 'run', 'Lead_scoring_inference_pipeline', 'generating_models_prediction', 'scheduled__2023-01-08T09:00:00+00:00', '--job-id', '84', '--raw', '--subdir', 'DAGS_FOLDER/Lead_scoring_inference_pipeline/.ipynb_checkpoints/lead_scoring_inference_pipeline-checkpoint.py', '--cfg-path', '/tmp/tmppklordwh', '--error-file', '/tmp/tmp60poa35v']
[2023-01-08 10:01:48,550] {standard_task_runner.py:80} INFO - Job 84: Subtask generating_models_prediction
[2023-01-08 10:01:48,594] {task_command.py:371} INFO - Running <TaskInstance: Lead_scoring_inference_pipeline.generating_models_prediction scheduled__2023-01-08T09:00:00+00:00 [running]> on host 1f037b111ba5
[2023-01-08 10:01:48,753] {taskinstance.py:1589} INFO - Exporting the following env vars:
AIRFLOW_CTX_DAG_OWNER=airflow
AIRFLOW_CTX_DAG_ID=Lead_scoring_inference_pipeline
AIRFLOW_CTX_TASK_ID=generating_models_prediction
AIRFLOW_CTX_EXECUTION_DATE=2023-01-08T09:00:00+00:00
AIRFLOW_CTX_TRY_NUMBER=2
AIRFLOW_CTX_DAG_RUN_ID=scheduled__2023-01-08T09:00:00+00:00
[2023-01-08 10:01:48,812] {connectionpool.py:780} WARNING - Retrying (Retry(total=4, connect=4, read=5, redirect=5, status=5)) after connection broken by 'NewConnectionError('<urllib3.connection.HTTPConnection object at 0x7fc787f5f670>: Failed to establish a new connection: [Errno 111] Connection refused')': /api/2.0/mlflow/registered-models/get-latest-versions
[2023-01-08 10:01:52,817] {connectionpool.py:780} WARNING - Retrying (Retry(total=3, connect=3, read=5, redirect=5, status=5)) after connection broken by 'NewConnectionError('<urllib3.connection.HTTPConnection object at 0x7fc787f5f400>: Failed to establish a new connection: [Errno 111] Connection refused')': /api/2.0/mlflow/registered-models/get-latest-versions
[2023-01-08 10:02:00,826] {connectionpool.py:780} WARNING - Retrying (Retry(total=2, connect=2, read=5, redirect=5, status=5)) after connection broken by 'NewConnectionError('<urllib3.connection.HTTPConnection object at 0x7fc787f5f310>: Failed to establish a new connection: [Errno 111] Connection refused')': /api/2.0/mlflow/registered-models/get-latest-versions
[2023-01-08 10:02:16,844] {connectionpool.py:780} WARNING - Retrying (Retry(total=1, connect=1, read=5, redirect=5, status=5)) after connection broken by 'NewConnectionError('<urllib3.connection.HTTPConnection object at 0x7fc787f51310>: Failed to establish a new connection: [Errno 111] Connection refused')': /api/2.0/mlflow/registered-models/get-latest-versions
[2023-01-08 10:02:48,873] {connectionpool.py:780} WARNING - Retrying (Retry(total=0, connect=0, read=5, redirect=5, status=5)) after connection broken by 'NewConnectionError('<urllib3.connection.HTTPConnection object at 0x7fc787f240d0>: Failed to establish a new connection: [Errno 111] Connection refused')': /api/2.0/mlflow/registered-models/get-latest-versions
[2023-01-08 10:02:48,875] {taskinstance.py:1909} ERROR - Task failed with exception
Traceback (most recent call last):
  File "/opt/conda/lib/python3.8/site-packages/urllib3/connection.py", line 174, in _new_conn
    conn = connection.create_connection(
  File "/opt/conda/lib/python3.8/site-packages/urllib3/util/connection.py", line 96, in create_connection
    raise err
  File "/opt/conda/lib/python3.8/site-packages/urllib3/util/connection.py", line 86, in create_connection
    sock.connect(sa)
ConnectionRefusedError: [Errno 111] Connection refused

During handling of the above exception, another exception occurred:

Traceback (most recent call last):
  File "/opt/conda/lib/python3.8/site-packages/urllib3/connectionpool.py", line 699, in urlopen
    httplib_response = self._make_request(
  File "/opt/conda/lib/python3.8/site-packages/urllib3/connectionpool.py", line 394, in _make_request
    conn.request(method, url, **httplib_request_kw)
  File "/opt/conda/lib/python3.8/site-packages/urllib3/connection.py", line 239, in request
    super(HTTPConnection, self).request(method, url, body=body, headers=headers)
  File "/opt/conda/lib/python3.8/http/client.py", line 1256, in request
    self._send_request(method, url, body, headers, encode_chunked)
  File "/opt/conda/lib/python3.8/http/client.py", line 1302, in _send_request
    self.endheaders(body, encode_chunked=encode_chunked)
  File "/opt/conda/lib/python3.8/http/client.py", line 1251, in endheaders
    self._send_output(message_body, encode_chunked=encode_chunked)
  File "/opt/conda/lib/python3.8/http/client.py", line 1011, in _send_output
    self.send(msg)
  File "/opt/conda/lib/python3.8/http/client.py", line 951, in send
    self.connect()
  File "/opt/conda/lib/python3.8/site-packages/urllib3/connection.py", line 205, in connect
    conn = self._new_conn()
  File "/opt/conda/lib/python3.8/site-packages/urllib3/connection.py", line 186, in _new_conn
    raise NewConnectionError(
urllib3.exceptions.NewConnectionError: <urllib3.connection.HTTPConnection object at 0x7fc787f24cd0>: Failed to establish a new connection: [Errno 111] Connection refused

During handling of the above exception, another exception occurred:

Traceback (most recent call last):
  File "/opt/conda/lib/python3.8/site-packages/requests/adapters.py", line 439, in send
    resp = conn.urlopen(
  File "/opt/conda/lib/python3.8/site-packages/urllib3/connectionpool.py", line 783, in urlopen
    return self.urlopen(
  File "/opt/conda/lib/python3.8/site-packages/urllib3/connectionpool.py", line 783, in urlopen
    return self.urlopen(
  File "/opt/conda/lib/python3.8/site-packages/urllib3/connectionpool.py", line 783, in urlopen
    return self.urlopen(
  [Previous line repeated 2 more times]
  File "/opt/conda/lib/python3.8/site-packages/urllib3/connectionpool.py", line 755, in urlopen
    retries = retries.increment(
  File "/opt/conda/lib/python3.8/site-packages/urllib3/util/retry.py", line 574, in increment
    raise MaxRetryError(_pool, url, error or ResponseError(cause))
urllib3.exceptions.MaxRetryError: HTTPConnectionPool(host='0.0.0.0', port=6007): Max retries exceeded with url: /api/2.0/mlflow/registered-models/get-latest-versions (Caused by NewConnectionError('<urllib3.connection.HTTPConnection object at 0x7fc787f24cd0>: Failed to establish a new connection: [Errno 111] Connection refused'))

During handling of the above exception, another exception occurred:

Traceback (most recent call last):
  File "/opt/conda/lib/python3.8/site-packages/mlflow/utils/rest_utils.py", line 151, in http_request
    return _get_http_response_with_retries(
  File "/opt/conda/lib/python3.8/site-packages/mlflow/utils/rest_utils.py", line 91, in _get_http_response_with_retries
    return session.request(method, url, **kwargs)
  File "/opt/conda/lib/python3.8/site-packages/requests/sessions.py", line 542, in request
    resp = self.send(prep, **send_kwargs)
  File "/opt/conda/lib/python3.8/site-packages/requests/sessions.py", line 655, in send
    r = adapter.send(request, **kwargs)
  File "/opt/conda/lib/python3.8/site-packages/requests/adapters.py", line 516, in send
    raise ConnectionError(e, request=request)
requests.exceptions.ConnectionError: HTTPConnectionPool(host='0.0.0.0', port=6007): Max retries exceeded with url: /api/2.0/mlflow/registered-models/get-latest-versions (Caused by NewConnectionError('<urllib3.connection.HTTPConnection object at 0x7fc787f24cd0>: Failed to establish a new connection: [Errno 111] Connection refused'))

During handling of the above exception, another exception occurred:

Traceback (most recent call last):
  File "/opt/conda/lib/python3.8/site-packages/airflow/operators/python.py", line 171, in execute
    return_value = self.execute_callable()
  File "/opt/conda/lib/python3.8/site-packages/airflow/operators/python.py", line 189, in execute_callable
    return self.python_callable(*self.op_args, **self.op_kwargs)
  File "/home/airflow/dags/Lead_scoring_inference_pipeline/utils.py", line 113, in get_models_prediction
    loaded_model = mlflow.pyfunc.load_model(
  File "/opt/conda/lib/python3.8/site-packages/mlflow/pyfunc/__init__.py", line 716, in load_model
    local_path = _download_artifact_from_uri(artifact_uri=model_uri, output_path=dst_path)
  File "/opt/conda/lib/python3.8/site-packages/mlflow/tracking/artifact_utils.py", line 94, in _download_artifact_from_uri
    return get_artifact_repository(artifact_uri=root_uri).download_artifacts(
  File "/opt/conda/lib/python3.8/site-packages/mlflow/store/artifact/artifact_repository_registry.py", line 107, in get_artifact_repository
    return _artifact_repository_registry.get_artifact_repository(artifact_uri)
  File "/opt/conda/lib/python3.8/site-packages/mlflow/store/artifact/artifact_repository_registry.py", line 73, in get_artifact_repository
    return repository(artifact_uri)
  File "/opt/conda/lib/python3.8/site-packages/mlflow/store/artifact/models_artifact_repo.py", line 35, in __init__
    uri = ModelsArtifactRepository.get_underlying_uri(artifact_uri)
  File "/opt/conda/lib/python3.8/site-packages/mlflow/store/artifact/models_artifact_repo.py", line 68, in get_underlying_uri
    (name, version) = get_model_name_and_version(client, uri)
  File "/opt/conda/lib/python3.8/site-packages/mlflow/store/artifact/utils/models.py", line 74, in get_model_name_and_version
    return model_name, str(_get_latest_model_version(client, model_name, model_stage))
  File "/opt/conda/lib/python3.8/site-packages/mlflow/store/artifact/utils/models.py", line 28, in _get_latest_model_version
    latest = client.get_latest_versions(name, None if stage is None else [stage])
  File "/opt/conda/lib/python3.8/site-packages/mlflow/tracking/client.py", line 2048, in get_latest_versions
    return self._get_registry_client().get_latest_versions(name, stages)
  File "/opt/conda/lib/python3.8/site-packages/mlflow/tracking/_model_registry/client.py", line 149, in get_latest_versions
    return self.store.get_latest_versions(name, stages)
  File "/opt/conda/lib/python3.8/site-packages/mlflow/store/model_registry/rest_store.py", line 197, in get_latest_versions
    response_proto = self._call_endpoint(GetLatestVersions, req_body, call_all_endpoints=True)
  File "/opt/conda/lib/python3.8/site-packages/mlflow/store/model_registry/rest_store.py", line 61, in _call_endpoint
    return call_endpoints(self.get_host_creds(), endpoints, json_body, response_proto)
  File "/opt/conda/lib/python3.8/site-packages/mlflow/utils/rest_utils.py", line 267, in call_endpoints
    return call_endpoint(host_creds, endpoint, method, json_body, response_proto)
  File "/opt/conda/lib/python3.8/site-packages/mlflow/utils/rest_utils.py", line 253, in call_endpoint
    response = http_request(
  File "/opt/conda/lib/python3.8/site-packages/mlflow/utils/rest_utils.py", line 163, in http_request
    raise MlflowException("API request to %s failed with exception %s" % (url, e))
mlflow.exceptions.MlflowException: API request to http://0.0.0.0:6007/api/2.0/mlflow/registered-models/get-latest-versions failed with exception HTTPConnectionPool(host='0.0.0.0', port=6007): Max retries exceeded with url: /api/2.0/mlflow/registered-models/get-latest-versions (Caused by NewConnectionError('<urllib3.connection.HTTPConnection object at 0x7fc787f24cd0>: Failed to establish a new connection: [Errno 111] Connection refused'))
[2023-01-08 10:02:48,888] {taskinstance.py:1415} INFO - Marking task as FAILED. dag_id=Lead_scoring_inference_pipeline, task_id=generating_models_prediction, execution_date=20230108T090000, start_date=20230108T100148, end_date=20230108T100248
[2023-01-08 10:02:48,916] {standard_task_runner.py:92} ERROR - Failed to execute job 84 for task generating_models_prediction (API request to http://0.0.0.0:6007/api/2.0/mlflow/registered-models/get-latest-versions failed with exception HTTPConnectionPool(host='0.0.0.0', port=6007): Max retries exceeded with url: /api/2.0/mlflow/registered-models/get-latest-versions (Caused by NewConnectionError('<urllib3.connection.HTTPConnection object at 0x7fc787f24cd0>: Failed to establish a new connection: [Errno 111] Connection refused')); 11184)
[2023-01-08 10:02:48,953] {local_task_job.py:156} INFO - Task exited with return code 1
[2023-01-08 10:02:48,985] {local_task_job.py:273} INFO - 0 downstream tasks scheduled from follow-on schedule check
